[32m2025-07-01 11:50:55 +0200[0m - dagster - [34mDEBUG[0m - jaffle_shop_parallel_job - 92fba2ff-540f-47b2-9fea-1b06012ae0fc - 23436 - LOGS_CAPTURED - Started capturing logs in process (pid: 23436).
[32m2025-07-01 11:50:55 +0200[0m - dagster - [34mDEBUG[0m - jaffle_shop_parallel_job - 92fba2ff-540f-47b2-9fea-1b06012ae0fc - 23436 - jaffle_shop_customers - STEP_START - Started execution of step "jaffle_shop_customers".
/Users/dlthubgtm/Desktop/Aashish/Dagster Demo/Second Test/.venv/lib/python3.11/site-packages/google/cloud/bigquery/client.py:610: UserWarning: Cannot create BigQuery Storage client, the dependency google-cloud-bigquery-storage is not installed.
  warnings.warn(
2025-07-01 11:51:01,914|[WARNING]|23436|8517099264|dlt|pool_runner.py|run_pool:99|Exiting runner due to signal 2
2025-07-01 11:51:03,404|[ERROR]|23436|6341865472|dlt|load.py|w_run_job:247|Terminal exception in job customers.8a5bcfc137.jsonl in file /Users/dlthubgtm/.dlt/pipelines/jaffle_shop_customers_bigquery/load/normalized/1751363457.043731/started_jobs/customers.8a5bcfc137.0.jsonl
Traceback (most recent call last):
  File "/Users/dlthubgtm/Desktop/Aashish/Dagster Demo/Second Test/.venv/lib/python3.11/site-packages/dlt/common/destination/client.py", line 404, in run_managed
    self.run()
  File "/Users/dlthubgtm/Desktop/Aashish/Dagster Demo/Second Test/.venv/lib/python3.11/site-packages/dlt/destinations/impl/bigquery/bigquery.py", line 99, in run
    sleep(1)
  File "/Users/dlthubgtm/Desktop/Aashish/Dagster Demo/Second Test/.venv/lib/python3.11/site-packages/dlt/common/runtime/signals.py", line 43, in sleep
    raise_if_signalled()
  File "/Users/dlthubgtm/Desktop/Aashish/Dagster Demo/Second Test/.venv/lib/python3.11/site-packages/dlt/common/runtime/signals.py", line 32, in raise_if_signalled
    raise SignalReceivedException(_received_signal)
dlt.common.exceptions.SignalReceivedException: Signal 2 received
[32m2025-07-01 11:51:03 +0200[0m - dagster - [34mERROR[0m - [31mjaffle_shop_parallel_job - 92fba2ff-540f-47b2-9fea-1b06012ae0fc - 23436 - jaffle_shop_customers - STEP_FAILURE - Execution of step "jaffle_shop_customers" failed.

dlt.common.exceptions.SignalReceivedException: Signal 2 received

Stack Trace:
  File "/Users/dlthubgtm/Desktop/Aashish/Dagster Demo/Second Test/.venv/lib/python3.11/site-packages/dagster/_core/execution/plan/execute_plan.py", line 246, in dagster_event_sequence_for_step
    yield from check.generator(step_events)
  File "/Users/dlthubgtm/Desktop/Aashish/Dagster Demo/Second Test/.venv/lib/python3.11/site-packages/dagster/_core/execution/plan/execute_step.py", line 502, in core_dagster_event_sequence_for_step
    for user_event in _step_output_error_checked_user_event_sequence(
  File "/Users/dlthubgtm/Desktop/Aashish/Dagster Demo/Second Test/.venv/lib/python3.11/site-packages/dagster/_core/execution/plan/execute_step.py", line 183, in _step_output_error_checked_user_event_sequence
    for user_event in user_event_sequence:
  File "/Users/dlthubgtm/Desktop/Aashish/Dagster Demo/Second Test/.venv/lib/python3.11/site-packages/dagster/_core/execution/plan/execute_step.py", line 90, in _process_asset_results_to_events
    for user_event in user_event_sequence:
  File "/Users/dlthubgtm/Desktop/Aashish/Dagster Demo/Second Test/.venv/lib/python3.11/site-packages/dagster/_core/execution/plan/compute.py", line 187, in execute_core_compute
    for step_output in _yield_compute_results(step_context, inputs, compute_fn, compute_context):
  File "/Users/dlthubgtm/Desktop/Aashish/Dagster Demo/Second Test/.venv/lib/python3.11/site-packages/dagster/_core/execution/plan/compute.py", line 156, in _yield_compute_results
    for event in iterate_with_context(
  File "/Users/dlthubgtm/Desktop/Aashish/Dagster Demo/Second Test/.venv/lib/python3.11/site-packages/dagster/_utils/__init__.py", line 392, in iterate_with_context
    next_output = next(iterator)
                  ^^^^^^^^^^^^^^
  File "/Users/dlthubgtm/Desktop/Aashish/dlthub-education/workshops/demo_dagster/dlt-dagster-integration-parallel-pipeline/dlt_dagster_integration_parallel_pipeline/assets.py", line 33, in asset
    yield from dlt.run(context=context)
  File "/Users/dlthubgtm/Desktop/Aashish/Dagster Demo/Second Test/.venv/lib/python3.11/site-packages/dagster_dlt/dlt_event_iterator.py", line 77, in __next__
    return next(self._inner_iterator)
           ^^^^^^^^^^^^^^^^^^^^^^^^^^
  File "/Users/dlthubgtm/Desktop/Aashish/Dagster Demo/Second Test/.venv/lib/python3.11/site-packages/dagster_dlt/resource.py", line 284, in _run
    load_info = dlt_pipeline.run(dlt_source, **kwargs)
                ^^^^^^^^^^^^^^^^^^^^^^^^^^^^^^^^^^^^^^
  File "/Users/dlthubgtm/Desktop/Aashish/Dagster Demo/Second Test/.venv/lib/python3.11/site-packages/dlt/pipeline/pipeline.py", line 222, in _wrap
    step_info = f(self, *args, **kwargs)
                ^^^^^^^^^^^^^^^^^^^^^^^^
  File "/Users/dlthubgtm/Desktop/Aashish/Dagster Demo/Second Test/.venv/lib/python3.11/site-packages/dlt/pipeline/pipeline.py", line 271, in _wrap
    return f(self, *args, **kwargs)
           ^^^^^^^^^^^^^^^^^^^^^^^^
  File "/Users/dlthubgtm/Desktop/Aashish/Dagster Demo/Second Test/.venv/lib/python3.11/site-packages/dlt/pipeline/pipeline.py", line 729, in run
    return self.load(destination, dataset_name, credentials=credentials)
           ^^^^^^^^^^^^^^^^^^^^^^^^^^^^^^^^^^^^^^^^^^^^^^^^^^^^^^^^^^^^^
  File "/Users/dlthubgtm/Desktop/Aashish/Dagster Demo/Second Test/.venv/lib/python3.11/site-packages/dlt/pipeline/pipeline.py", line 222, in _wrap
    step_info = f(self, *args, **kwargs)
                ^^^^^^^^^^^^^^^^^^^^^^^^
  File "/Users/dlthubgtm/Desktop/Aashish/Dagster Demo/Second Test/.venv/lib/python3.11/site-packages/dlt/pipeline/pipeline.py", line 162, in _wrap
    return f(self, *args, **kwargs)
           ^^^^^^^^^^^^^^^^^^^^^^^^
  File "/Users/dlthubgtm/Desktop/Aashish/Dagster Demo/Second Test/.venv/lib/python3.11/site-packages/dlt/pipeline/pipeline.py", line 271, in _wrap
    return f(self, *args, **kwargs)
           ^^^^^^^^^^^^^^^^^^^^^^^^
  File "/Users/dlthubgtm/Desktop/Aashish/Dagster Demo/Second Test/.venv/lib/python3.11/site-packages/dlt/pipeline/pipeline.py", line 585, in load
    runner.run_pool(load_step.config, load_step)
  File "/Users/dlthubgtm/Desktop/Aashish/Dagster Demo/Second Test/.venv/lib/python3.11/site-packages/dlt/common/runners/pool_runner.py", line 91, in run_pool
    while _run_func():
          ^^^^^^^^^^^
  File "/Users/dlthubgtm/Desktop/Aashish/Dagster Demo/Second Test/.venv/lib/python3.11/site-packages/dlt/common/runners/pool_runner.py", line 84, in _run_func
    run_metrics = run_f.run(cast(TExecutor, pool))
                  ^^^^^^^^^^^^^^^^^^^^^^^^^^^^^^^^
  File "/Users/dlthubgtm/Desktop/Aashish/Dagster Demo/Second Test/.venv/lib/python3.11/site-packages/dlt/load/load.py", line 638, in run
    self.load_single_package(load_id, schema)
  File "/Users/dlthubgtm/Desktop/Aashish/Dagster Demo/Second Test/.venv/lib/python3.11/site-packages/dlt/load/load.py", line 600, in load_single_package
    sleep(self._run_loop_sleep_duration)
  File "/Users/dlthubgtm/Desktop/Aashish/Dagster Demo/Second Test/.venv/lib/python3.11/site-packages/dlt/common/runtime/signals.py", line 48, in sleep
    raise_if_signalled()
  File "/Users/dlthubgtm/Desktop/Aashish/Dagster Demo/Second Test/.venv/lib/python3.11/site-packages/dlt/common/runtime/signals.py", line 32, in raise_if_signalled
    raise SignalReceivedException(_received_signal)
[0m
